Workbook

Sheet Instructions
B2: CTS Social · Airtable → Publer CSV Converter
B3: 每周批量排期工作流（方案 C · 无 Zapier）
B6: Step 1 · Airtable
B7: 在 Airtable 的 'Zapier_Ready' 视图里，挑好本批要发的帖子，确保 Status=ready、有 Image_URL、有 Caption_EN。
B9: Step 2 · 导出 CSV
B10: Airtable 视图右上 Share and Sync → Download CSV。得到一个 .csv 文件。
B12: Step 3 · 粘贴到此模板
B13: 打开那个 .csv（用 Excel 或 Numbers）→ Ctrl+A 全选 → 复制 → 粘贴到本文件的 'Airtable Input' sheet 的 A1 开始。
B15: Step 4 · 看 Publer Output
B16: 切到 'Publer Output' sheet，公式会自动填好 Publer 要求的 12 列格式。
B18: Step 5 · 另存为 CSV
B19: File → Save As → 格式选 CSV UTF-8 (.csv) → 命名比如 'cts-week1-to-publer.csv'。注意：只保存 'Publer Output' 这个 sheet！
... B40: 模板版本：v1 · 2026-04-25 · Made for CTS Tours

Sheet Airtable Input
A1: Headline_EN | B1: Date | C1: Day_of_Week | D1: Time_NZST | E1: Platform | F1: Product | G1: Format | H1: Ratio | I1: Caption_EN | J1: Hashtags_IG | K1: URL_Organic_UTM | L1: LoveArt_Prompt_EN | M1: Image_URL | N1: Status | O1: Internal_Notes_ZH | P1: Content_Pillar | Q1: Content_Summary_EN | R1: Zapier_Synced | S1: Publer_Post_ID
A2: Sample · Do You Need a Visa? | B2: 2026-04-26 | C2: Sunday | D2: 07:00 | E2: Facebook | F2: Visa-Free Education | G2: Feed | H2: 4:5 | I2: 🛫 Planning your China trip? One question we hear from kiwi travellers: 'Do I need a visa?' | J2: #ChinaVisa #NZTravel #CTSTours | K2: https://www.ctstours.co.nz/china-visa-guide | M2: https://qbturrydultenhlfmdcm.supabase.co/storage/v1/object/public/tour-images/forbidden-city-aerial.jpg | N2: ready | R2: FALSE
A50: ↑ 把 Airtable 导出的 CSV 从 A2 开始粘贴（可以覆盖上面的 headers，Excel 会自动匹配）

Sheet Publer Output
A1: Date | B1: Message | C1: Link | D1: Media URLs | E1: Title | F1: Labels | G1: Alt Text(s) | H1: Comment(s) | I1: Subtype | J1: Call-to-Action
A2: =IFERROR(IF(INDEX('Airtable Input'!$A:$Z, 2, MATCH("Date", 'Airtable Input'!$1:$1, 0))="","",SUBSTITUTE(TEXT(INDEX('Airtable Input'!$A:$Z, 2, MATCH("Date", 'Airtable Input'!$1:$1, 0)),"YYYY-MM-DD"),"-","/")&" "&INDEX('Airtable Input'!$A:$Z, 2, MATCH("Time_NZST", 'Airtable Input'!$1:$1, 0))),"") -> 2026/04/26 07:00 | B2: =IFERROR(IF(INDEX('Airtable Input'!$A:$Z, 2, MATCH("Caption_EN", 'Airtable Input'!$1:$1, 0))="","",INDEX('Airtable Input'!$A:$Z, 2, MATCH("Caption_EN", 'Airtable Input'!$1:$1, 0))&CHAR(10)&CHAR(10)&INDEX('Airtable Input'!$A:$Z, 2, MATCH("Hashtags_IG", 'Airtable Input'!$1:$1, 0))),"") -> 🛫 Planning your China trip? One question we hear from kiwi travellers: 'Do I need a visa?' #ChinaVisa #NZTravel #CTSTours | D2: =IFERROR(INDEX('Airtable Input'!$A:$Z, 2, MATCH("Image_URL", 'Airtable Input'!$1:$1, 0)),"") -> https://qbturrydultenhlfmdcm.supabase.co/storage/v1/object/public/tour-images/forbidden-city-aerial.jpg | G2: =IFERROR(INDEX('Airtable Input'!$A:$Z, 2, MATCH("Headline_EN", 'Airtable Input'!$1:$1, 0)),"") -> Sample · Do You Need a Visa? | H2: =IFERROR(IF(INDEX('Airtable Input'!$A:$Z, 2, MATCH("URL_Organic_UTM", 'Airtable Input'!$1:$1, 0))="","","🔗 Full details: "&INDEX('Airtable Input'!$A:$Z, 2, MATCH("URL_Organic_UTM", 'Airtable Input'!$1:$1, 0))),"") -> 🔗 Full details: https://www.ctstours.co.nz/china-visa-guide | I2: =IFERROR(IF(INDEX('Airtable Input'!$A:$Z, 2, MATCH("Format", 'Airtable Input'!$1:$1, 0))="Reel","Reel",IF(INDEX('Airtable Input'!$A:$Z, 2, MATCH("Format", 'Airtable Input'!$1:$1, 0))="Story","Story","")),"")
A3: =IFERROR(IF(INDEX('Airtable Input'!$A:$Z, 3, MATCH("Date", 'Airtable Input'!$1:$1, 0))="","",SUBSTITUTE(TEXT(INDEX('Airtable Input'!$A:$Z, 3, MATCH("Date", 'Airtable Input'!$1:$1, 0)),"YYYY-MM-DD"),"-","/")&" "&INDEX('Airtable Input'!$A:$Z, 3, MATCH("Time_NZST", 'Airtable Input'!$1:$1, 0))),"") | B3: =IFERROR(IF(INDEX('Airtable Input'!$A:$Z, 3, MATCH("Caption_EN", 'Airtable Input'!$1:$1, 0))="","",INDEX('Airtable Input'!$A:$Z, 3, MATCH("Caption_EN", 'Airtable Input'!$1:$1, 0))&CHAR(10)&CHAR(10)&INDEX('Airtable Input'!$A:$Z, 3, MATCH("Hashtags_IG", 'Airtable Input'!$1:$1, 0))),"") | D3: =IFERROR(INDEX('Airtable Input'!$A:$Z, 3, MATCH("Image_URL", 'Airtable Input'!$1:$1, 0)),"") -> 0 | G3: =IFERROR(INDEX('Airtable Input'!$A:$Z, 3, MATCH("Headline_EN", 'Airtable Input'!$1:$1, 0)),"") -> 0 | H3: =IFERROR(IF(INDEX('Airtable Input'!$A:$Z, 3, MATCH("URL_Organic_UTM", 'Airtable Input'!$1:$1, 0))="","","🔗 Full details: "&INDEX('Airtable Input'!$A:$Z, 3, MATCH("URL_Organic_UTM", 'Airtable Input'!$1:$1, 0))),"") | I3: =IFERROR(IF(INDEX('Airtable Input'!$A:$Z, 3, MATCH("Format", 'Airtable Input'!$1:$1, 0))="Reel","Reel",IF(INDEX('Airtable Input'!$A:$Z, 3, MATCH("Format", 'Airtable Input'!$1:$1, 0))="Story","Story","")),"")
A4: =IFERROR(IF(INDEX('Airtable Input'!$A:$Z, 4, MATCH("Date", 'Airtable Input'!$1:$1, 0))="","",SUBSTITUTE(TEXT(INDEX('Airtable Input'!$A:$Z, 4, MATCH("Date", 'Airtable Input'!$1:$1, 0)),"YYYY-MM-DD"),"-","/")&" "&INDEX('Airtable Input'!$A:$Z, 4, MATCH("Time_NZST", 'Airtable Input'!$1:$1, 0))),"") | B4: =IFERROR(IF(INDEX('Airtable Input'!$A:$Z, 4, MATCH("Caption_EN", 'Airtable Input'!$1:$1, 0))="","",INDEX('Airtable Input'!$A:$Z, 4, MATCH("Caption_EN", 'Airtable Input'!$1:$1, 0))&CHAR(10)&CHAR(10)&INDEX('Airtable Input'!$A:$Z, 4, MATCH("Hashtags_IG", 'Airtable Input'!$1:$1, 0))),"") | D4: =IFERROR(INDEX('Airtable Input'!$A:$Z, 4, MATCH("Image_URL", 'Airtable Input'!$1:$1, 0)),"") -> 0 | G4: =IFERROR(INDEX('Airtable Input'!$A:$Z, 4, MATCH("Headline_EN", 'Airtable Input'!$1:$1, 0)),"") -> 0 | H4: =IFERROR(IF(INDEX('Airtable Input'!$A:$Z, 4, MATCH("URL_Organic_UTM", 'Airtable Input'!$1:$1, 0))="","","🔗 Full details: "&INDEX('Airtable Input'!$A:$Z, 4, MATCH("URL_Organic_UTM", 'Airtable Input'!$1:$1, 0))),"") | I4: =IFERROR(IF(INDEX('Airtable Input'!$A:$Z, 4, MATCH("Format", 'Airtable Input'!$1:$1, 0))="Reel","Reel",IF(INDEX('Airtable Input'!$A:$Z, 4, MATCH("Format", 'Airtable Input'!$1:$1, 0))="Story","Story","")),"")
A5: =IFERROR(IF(INDEX('Airtable Input'!$A:$Z, 5, MATCH("Date", 'Airtable Input'!$1:$1, 0))="","",SUBSTITUTE(TEXT(INDEX('Airtable Input'!$A:$Z, 5, MATCH("Date", 'Airtable Input'!$1:$1, 0)),"YYYY-MM-DD"),"-","/")&" "&INDEX('Airtable Input'!$A:$Z, 5, MATCH("Time_NZST", 'Airtable Input'!$1:$1, 0))),"") | B5: =IFERROR(IF(INDEX('Airtable Input'!$A:$Z, 5, MATCH("Caption_EN", 'Airtable Input'!$1:$1, 0))="","",INDEX('Airtable Input'!$A:$Z, 5, MATCH("Caption_EN", 'Airtable Input'!$1:$1, 0))&CHAR(10)&CHAR(10)&INDEX('Airtable Input'!$A:$Z, 5, MATCH("Hashtags_IG", 'Airtable Input'!$1:$1, 0))),"") | D5: =IFERROR(INDEX('Airtable Input'!$A:$Z, 5, MATCH("Image_URL", 'Airtable Input'!$1:$1, 0)),"") -> 0 | G5: =IFERROR(INDEX('Airtable Input'!$A:$Z, 5, MATCH("Headline_EN", 'Airtable Input'!$1:$1, 0)),"") -> 0 | H5: =IFERROR(IF(INDEX('Airtable Input'!$A:$Z, 5, MATCH("URL_Organic_UTM", 'Airtable Input'!$1:$1, 0))="","","🔗 Full details: "&INDEX('Airtable Input'!$A:$Z, 5, MATCH("URL_Organic_UTM", 'Airtable Input'!$1:$1, 0))),"") | I5: =IFERROR(IF(INDEX('Airtable Input'!$A:$Z, 5, MATCH("Format", 'Airtable Input'!$1:$1, 0))="Reel","Reel",IF(INDEX('Airtable Input'!$A:$Z, 5, MATCH("Format", 'Airtable Input'!$1:$1, 0))="Story","Story","")),"")
A6: =IFERROR(IF(INDEX('Airtable Input'!$A:$Z, 6, MATCH("Date", 'Airtable Input'!$1:$1, 0))="","",SUBSTITUTE(TEXT(INDEX('Airtable Input'!$A:$Z, 6, MATCH("Date", 'Airtable Input'!$1:$1, 0)),"YYYY-MM-DD"),"-","/")&" "&INDEX('Airtable Input'!$A:$Z, 6, MATCH("Time_NZST", 'Airtable Input'!$1:$1, 0))),"") | B6: =IFERROR(IF(INDEX('Airtable Input'!$A:$Z, 6, MATCH("Caption_EN", 'Airtable Input'!$1:$1, 0))="","",INDEX('Airtable Input'!$A:$Z, 6, MATCH("Caption_EN", 'Airtable Input'!$1:$1, 0))&CHAR(10)&CHAR(10)&INDEX('Airtable Input'!$A:$Z, 6, MATCH("Hashtags_IG", 'Airtable Input'!$1:$1, 0))),"") | D6: =IFERROR(INDEX('Airtable Input'!$A:$Z, 6, MATCH("Image_URL", 'Airtable Input'!$1:$1, 0)),"") -> 0 | G6: =IFERROR(INDEX('Airtable Input'!$A:$Z, 6, MATCH("Headline_EN", 'Airtable Input'!$1:$1, 0)),"") -> 0 | H6: =IFERROR(IF(INDEX('Airtable Input'!$A:$Z, 6, MATCH("URL_Organic_UTM", 'Airtable Input'!$1:$1, 0))="","","🔗 Full details: "&INDEX('Airtable Input'!$A:$Z, 6, MATCH("URL_Organic_UTM", 'Airtable Input'!$1:$1, 0))),"") | I6: =IFERROR(IF(INDEX('Airtable Input'!$A:$Z, 6, MATCH("Format", 'Airtable Input'!$1:$1, 0))="Reel","Reel",IF(INDEX('Airtable Input'!$A:$Z, 6, MATCH("Format", 'Airtable Input'!$1:$1, 0))="Story","Story","")),"")
A7: =IFERROR(IF(INDEX('Airtable Input'!$A:$Z, 7, MATCH("Date", 'Airtable Input'!$1:$1, 0))="","",SUBSTITUTE(TEXT(INDEX('Airtable Input'!$A:$Z, 7, MATCH("Date", 'Airtable Input'!$1:$1, 0)),"YYYY-MM-DD"),"-","/")&" "&INDEX('Airtable Input'!$A:$Z, 7, MATCH("Time_NZST", 'Airtable Input'!$1:$1, 0))),"") | B7: =IFERROR(IF(INDEX('Airtable Input'!$A:$Z, 7, MATCH("Caption_EN", 'Airtable Input'!$1:$1, 0))="","",INDEX('Airtable Input'!$A:$Z, 7, MATCH("Caption_EN", 'Airtable Input'!$1:$1, 0))&CHAR(10)&CHAR(10)&INDEX('Airtable Input'!$A:$Z, 7, MATCH("Hashtags_IG", 'Airtable Input'!$1:$1, 0))),"") | D7: =IFERROR(INDEX('Airtable Input'!$A:$Z, 7, MATCH("Image_URL", 'Airtable Input'!$1:$1, 0)),"") -> 0 | G7: =IFERROR(INDEX('Airtable Input'!$A:$Z, 7, MATCH("Headline_EN", 'Airtable Input'!$1:$1, 0)),"") -> 0 | H7: =IFERROR(IF(INDEX('Airtable Input'!$A:$Z, 7, MATCH("URL_Organic_UTM", 'Airtable Input'!$1:$1, 0))="","","🔗 Full details: "&INDEX('Airtable Input'!$A:$Z, 7, MATCH("URL_Organic_UTM", 'Airtable Input'!$1:$1, 0))),"") | I7: =IFERROR(IF(INDEX('Airtable Input'!$A:$Z, 7, MATCH("Format", 'Airtable Input'!$1:$1, 0))="Reel","Reel",IF(INDEX('Airtable Input'!$A:$Z, 7, MATCH("Format", 'Airtable Input'!$1:$1, 0))="Story","Story","")),"")
A8: =IFERROR(IF(INDEX('Airtable Input'!$A:$Z, 8, MATCH("Date", 'Airtable Input'!$1:$1, 0))="","",SUBSTITUTE(TEXT(INDEX('Airtable Input'!$A:$Z, 8, MATCH("Date", 'Airtable Input'!$1:$1, 0)),"YYYY-MM-DD"),"-","/")&" "&INDEX('Airtable Input'!$A:$Z, 8, MATCH("Time_NZST", 'Airtable Input'!$1:$1, 0))),"") | B8: =IFERROR(IF(INDEX('Airtable Input'!$A:$Z, 8, MATCH("Caption_EN", 'Airtable Input'!$1:$1, 0))="","",INDEX('Airtable Input'!$A:$Z, 8, MATCH("Caption_EN", 'Airtable Input'!$1:$1, 0))&CHAR(10)&CHAR(10)&INDEX('Airtable Input'!$A:$Z, 8, MATCH("Hashtags_IG", 'Airtable Input'!$1:$1, 0))),"") | D8: =IFERROR(INDEX('Airtable Input'!$A:$Z, 8, MATCH("Image_URL", 'Airtable Input'!$1:$1, 0)),"") -> 0 | G8: =IFERROR(INDEX('Airtable Input'!$A:$Z, 8, MATCH("Headline_EN", 'Airtable Input'!$1:$1, 0)),"") -> 0 | H8: =IFERROR(IF(INDEX('Airtable Input'!$A:$Z, 8, MATCH("URL_Organic_UTM", 'Airtable Input'!$1:$1, 0))="","","🔗 Full details: "&INDEX('Airtable Input'!$A:$Z, 8, MATCH("URL_Organic_UTM", 'Airtable Input'!$1:$1, 0))),"") | I8: =IFERROR(IF(INDEX('Airtable Input'!$A:$Z, 8, MATCH("Format", 'Airtable Input'!$1:$1, 0))="Reel","Reel",IF(INDEX('Airtable Input'!$A:$Z, 8, MATCH("Format", 'Airtable Input'!$1:$1, 0))="Story","Story","")),"")
A9: =IFERROR(IF(INDEX('Airtable Input'!$A:$Z, 9, MATCH("Date", 'Airtable Input'!$1:$1, 0))="","",SUBSTITUTE(TEXT(INDEX('Airtable Input'!$A:$Z, 9, MATCH("Date", 'Airtable Input'!$1:$1, 0)),"YYYY-MM-DD"),"-","/")&" "&INDEX('Airtable Input'!$A:$Z, 9, MATCH("Time_NZST", 'Airtable Input'!$1:$1, 0))),"") | B9: =IFERROR(IF(INDEX('Airtable Input'!$A:$Z, 9, MATCH("Caption_EN", 'Airtable Input'!$1:$1, 0))="","",INDEX('Airtable Input'!$A:$Z, 9, MATCH("Caption_EN", 'Airtable Input'!$1:$1, 0))&CHAR(10)&CHAR(10)&INDEX('Airtable Input'!$A:$Z, 9, MATCH("Hashtags_IG", 'Airtable Input'!$1:$1, 0))),"") | D9: =IFERROR(INDEX('Airtable Input'!$A:$Z, 9, MATCH("Image_URL", 'Airtable Input'!$1:$1, 0)),"") -> 0 | G9: =IFERROR(INDEX('Airtable Input'!$A:$Z, 9, MATCH("Headline_EN", 'Airtable Input'!$1:$1, 0)),"") -> 0 | H9: =IFERROR(IF(INDEX('Airtable Input'!$A:$Z, 9, MATCH("URL_Organic_UTM", 'Airtable Input'!$1:$1, 0))="","","🔗 Full details: "&INDEX('Airtable Input'!$A:$Z, 9, MATCH("URL_Organic_UTM", 'Airtable Input'!$1:$1, 0))),"") | I9: =IFERROR(IF(INDEX('Airtable Input'!$A:$Z, 9, MATCH("Format", 'Airtable Input'!$1:$1, 0))="Reel","Reel",IF(INDEX('Airtable Input'!$A:$Z, 9, MATCH("Format", 'Airtable Input'!$1:$1, 0))="Story","Story","")),"")
A10: =IFERROR(IF(INDEX('Airtable Input'!$A:$Z, 10, MATCH("Date", 'Airtable Input'!$1:$1, 0))="","",SUBSTITUTE(TEXT(INDEX('Airtable Input'!$A:$Z, 10, MATCH("Date", 'Airtable Input'!$1:$1, 0)),"YYYY-MM-DD"),"-","/")&" "&INDEX('Airtable Input'!$A:$Z, 10, MATCH("Time_NZST", 'Airtable Input'!$1:$1, 0))),"") | B10: =IFERROR(IF(INDEX('Airtable Input'!$A:$Z, 10, MATCH("Caption_EN", 'Airtable Input'!$1:$1, 0))="","",INDEX('Airtable Input'!$A:$Z, 10, MATCH("Caption_EN", 'Airtable Input'!$1:$1, 0))&CHAR(10)&CHAR(10)&INDEX('Airtable Input'!$A:$Z, 10, MATCH("Hashtags_IG", 'Airtable Input'!$1:$1, 0))),"") | D10: =IFERROR(INDEX('Airtable Input'!$A:$Z, 10, MATCH("Image_URL", 'Airtable Input'!$1:$1, 0)),"") -> 0 | G10: =IFERROR(INDEX('Airtable Input'!$A:$Z, 10, MATCH("Headline_EN", 'Airtable Input'!$1:$1, 0)),"") -> 0 | H10: =IFERROR(IF(INDEX('Airtable Input'!$A:$Z, 10, MATCH("URL_Organic_UTM", 'Airtable Input'!$1:$1, 0))="","","🔗 Full details: "&INDEX('Airtable Input'!$A:$Z, 10, MATCH("URL_Organic_UTM", 'Airtable Input'!$1:$1, 0))),"") | I10: =IFERROR(IF(INDEX('Airtable Input'!$A:$Z, 10, MATCH("Format", 'Airtable Input'!$1:$1, 0))="Reel","Reel",IF(INDEX('Airtable Input'!$A:$Z, 10, MATCH("Format", 'Airtable Input'!$1:$1, 0))="Story","Story","")),"")
A11: =IFERROR(IF(INDEX('Airtable Input'!$A:$Z, 11, MATCH("Date", 'Airtable Input'!$1:$1, 0))="","",SUBSTITUTE(TEXT(INDEX('Airtable Input'!$A:$Z, 11, MATCH("Date", 'Airtable Input'!$1:$1, 0)),"YYYY-MM-DD"),"-","/")&" "&INDEX('Airtable Input'!$A:$Z, 11, MATCH("Time_NZST", 'Airtable Input'!$1:$1, 0))),"") | B11: =IFERROR(IF(INDEX('Airtable Input'!$A:$Z, 11, MATCH("Caption_EN", 'Airtable Input'!$1:$1, 0))="","",INDEX('Airtable Input'!$A:$Z, 11, MATCH("Caption_EN", 'Airtable Input'!$1:$1, 0))&CHAR(10)&CHAR(10)&INDEX('Airtable Input'!$A:$Z, 11, MATCH("Hashtags_IG", 'Airtable Input'!$1:$1, 0))),"") | D11: =IFERROR(INDEX('Airtable Input'!$A:$Z, 11, MATCH("Image_URL", 'Airtable Input'!$1:$1, 0)),"") -> 0 | G11: =IFERROR(INDEX('Airtable Input'!$A:$Z, 11, MATCH("Headline_EN", 'Airtable Input'!$1:$1, 0)),"") -> 0 | H11: =IFERROR(IF(INDEX('Airtable Input'!$A:$Z, 11, MATCH("URL_Organic_UTM", 'Airtable Input'!$1:$1, 0))="","","🔗 Full details: "&INDEX('Airtable Input'!$A:$Z, 11, MATCH("URL_Organic_UTM", 'Airtable Input'!$1:$1, 0))),"") | I11: =IFERROR(IF(INDEX('Airtable Input'!$A:$Z, 11, MATCH("Format", 'Airtable Input'!$1:$1, 0))="Reel","Reel",IF(INDEX('Airtable Input'!$A:$Z, 11, MATCH("Format", 'Airtable Input'!$1:$1, 0))="Story","Story","")),"")
A12: =IFERROR(IF(INDEX('Airtable Input'!$A:$Z, 12, MATCH("Date", 'Airtable Input'!$1:$1, 0))="","",SUBSTITUTE(TEXT(INDEX('Airtable Input'!$A:$Z, 12, MATCH("Date", 'Airtable Input'!$1:$1, 0)),"YYYY-MM-DD"),"-","/")&" "&INDEX('Airtable Input'!$A:$Z, 12, MATCH("Time_NZST", 'Airtable Input'!$1:$1, 0))),"") | B12: =IFERROR(IF(INDEX('Airtable Input'!$A:$Z, 12, MATCH("Caption_EN", 'Airtable Input'!$1:$1, 0))="","",INDEX('Airtable Input'!$A:$Z, 12, MATCH("Caption_EN", 'Airtable Input'!$1:$1, 0))&CHAR(10)&CHAR(10)&INDEX('Airtable Input'!$A:$Z, 12, MATCH("Hashtags_IG", 'Airtable Input'!$1:$1, 0))),"") | D12: =IFERROR(INDEX('Airtable Input'!$A:$Z, 12, MATCH("Image_URL", 'Airtable Input'!$1:$1, 0)),"") -> 0 | G12: =IFERROR(INDEX('Airtable Input'!$A:$Z, 12, MATCH("Headline_EN", 'Airtable Input'!$1:$1, 0)),"") -> 0 | H12: =IFERROR(IF(INDEX('Airtable Input'!$A:$Z, 12, MATCH("URL_Organic_UTM", 'Airtable Input'!$1:$1, 0))="","","🔗 Full details: "&INDEX('Airtable Input'!$A:$Z, 12, MATCH("URL_Organic_UTM", 'Airtable Input'!$1:$1, 0))),"") | I12: =IFERROR(IF(INDEX('Airtable Input'!$A:$Z, 12, MATCH("Format", 'Airtable Input'!$1:$1, 0))="Reel","Reel",IF(INDEX('Airtable Input'!$A:$Z, 12, MATCH("Format", 'Airtable Input'!$1:$1, 0))="Story","Story","")),"")
A13: =IFERROR(IF(INDEX('Airtable Input'!$A:$Z, 13, MATCH("Date", 'Airtable Input'!$1:$1, 0))="","",SUBSTITUTE(TEXT(INDEX('Airtable Input'!$A:$Z, 13, MATCH("Date", 'Airtable Input'!$1:$1, 0)),"YYYY-MM-DD"),"-","/")&" "&INDEX('Airtable Input'!$A:$Z, 13, MATCH("Time_NZST", 'Airtable Input'!$1:$1, 0))),"") | B13: =IFERROR(IF(INDEX('Airtable Input'!$A:$Z, 13, MATCH("Caption_EN", 'Airtable Input'!$1:$1, 0))="","",INDEX('Airtable Input'!$A:$Z, 13, MATCH("Caption_EN", 'Airtable Input'!$1:$1, 0))&CHAR(10)&CHAR(10)&INDEX('Airtable Input'!$A:$Z, 13, MATCH("Hashtags_IG", 'Airtable Input'!$1:$1, 0))),"") | D13: =IFERROR(INDEX('Airtable Input'!$A:$Z, 13, MATCH("Image_URL", 'Airtable Input'!$1:$1, 0)),"") -> 0 | G13: =IFERROR(INDEX('Airtable Input'!$A:$Z, 13, MATCH("Headline_EN", 'Airtable Input'!$1:$1, 0)),"") -> 0 | H13: =IFERROR(IF(INDEX('Airtable Input'!$A:$Z, 13, MATCH("URL_Organic_UTM", 'Airtable Input'!$1:$1, 0))="","","🔗 Full details: "&INDEX('Airtable Input'!$A:$Z, 13, MATCH("URL_Organic_UTM", 'Airtable Input'!$1:$1, 0))),"") | I13: =IFERROR(IF(INDEX('Airtable Input'!$A:$Z, 13, MATCH("Format", 'Airtable Input'!$1:$1, 0))="Reel","Reel",IF(INDEX('Airtable Input'!$A:$Z, 13, MATCH("Format", 'Airtable Input'!$1:$1, 0))="Story","Story","")),"")
A14: =IFERROR(IF(INDEX('Airtable Input'!$A:$Z, 14, MATCH("Date", 'Airtable Input'!$1:$1, 0))="","",SUBSTITUTE(TEXT(INDEX('Airtable Input'!$A:$Z, 14, MATCH("Date", 'Airtable Input'!$1:$1, 0)),"YYYY-MM-DD"),"-","/")&" "&INDEX('Airtable Input'!$A:$Z, 14, MATCH("Time_NZST", 'Airtable Input'!$1:$1, 0))),"") | B14: =IFERROR(IF(INDEX('Airtable Input'!$A:$Z, 14, MATCH("Caption_EN", 'Airtable Input'!$1:$1, 0))="","",INDEX('Airtable Input'!$A:$Z, 14, MATCH("Caption_EN", 'Airtable Input'!$1:$1, 0))&CHAR(10)&CHAR(10)&INDEX('Airtable Input'!$A:$Z, 14, MATCH("Hashtags_IG", 'Airtable Input'!$1:$1, 0))),"") | D14: =IFERROR(INDEX('Airtable Input'!$A:$Z, 14, MATCH("Image_URL", 'Airtable Input'!$1:$1, 0)),"") -> 0 | G14: =IFERROR(INDEX('Airtable Input'!$A:$Z, 14, MATCH("Headline_EN", 'Airtable Input'!$1:$1, 0)),"") -> 0 | H14: =IFERROR(IF(INDEX('Airtable Input'!$A:$Z, 14, MATCH("URL_Organic_UTM", 'Airtable Input'!$1:$1, 0))="","","🔗 Full details: "&INDEX('Airtable Input'!$A:$Z, 14, MATCH("URL_Organic_UTM", 'Airtable Input'!$1:$1, 0))),"") | I14: =IFERROR(IF(INDEX('Airtable Input'!$A:$Z, 14, MATCH("Format", 'Airtable Input'!$1:$1, 0))="Reel","Reel",IF(INDEX('Airtable Input'!$A:$Z, 14, MATCH("Format", 'Airtable Input'!$1:$1, 0))="Story","Story","")),"")
A15: =IFERROR(IF(INDEX('Airtable Input'!$A:$Z, 15, MATCH("Date", 'Airtable Input'!$1:$1, 0))="","",SUBSTITUTE(TEXT(INDEX('Airtable Input'!$A:$Z, 15, MATCH("Date", 'Airtable Input'!$1:$1, 0)),"YYYY-MM-DD"),"-","/")&" "&INDEX('Airtable Input'!$A:$Z, 15, MATCH("Time_NZST", 'Airtable Input'!$1:$1, 0))),"") | B15: =IFERROR(IF(INDEX('Airtable Input'!$A:$Z, 15, MATCH("Caption_EN", 'Airtable Input'!$1:$1, 0))="","",INDEX('Airtable Input'!$A:$Z, 15, MATCH("Caption_EN", 'Airtable Input'!$1:$1, 0))&CHAR(10)&CHAR(10)&INDEX('Airtable Input'!$A:$Z, 15, MATCH("Hashtags_IG", 'Airtable Input'!$1:$1, 0))),"") | D15: =IFERROR(INDEX('Airtable Input'!$A:$Z, 15, MATCH("Image_URL", 'Airtable Input'!$1:$1, 0)),"") -> 0 | G15: =IFERROR(INDEX('Airtable Input'!$A:$Z, 15, MATCH("Headline_EN", 'Airtable Input'!$1:$1, 0)),"") -> 0 | H15: =IFERROR(IF(INDEX('Airtable Input'!$A:$Z, 15, MATCH("URL_Organic_UTM", 'Airtable Input'!$1:$1, 0))="","","🔗 Full details: "&INDEX('Airtable Input'!$A:$Z, 15, MATCH("URL_Organic_UTM", 'Airtable Input'!$1:$1, 0))),"") | I15: =IFERROR(IF(INDEX('Airtable Input'!$A:$Z, 15, MATCH("Format", 'Airtable Input'!$1:$1, 0))="Reel","Reel",IF(INDEX('Airtable Input'!$A:$Z, 15, MATCH("Format", 'Airtable Input'!$1:$1, 0))="Story","Story","")),"")
A16: =IFERROR(IF(INDEX('Airtable Input'!$A:$Z, 16, MATCH("Date", 'Airtable Input'!$1:$1, 0))="","",SUBSTITUTE(TEXT(INDEX('Airtable Input'!$A:$Z, 16, MATCH("Date", 'Airtable Input'!$1:$1, 0)),"YYYY-MM-DD"),"-","/")&" "&INDEX('Airtable Input'!$A:$Z, 16, MATCH("Time_NZST", 'Airtable Input'!$1:$1, 0))),"") | B16: =IFERROR(IF(INDEX('Airtable Input'!$A:$Z, 16, MATCH("Caption_EN", 'Airtable Input'!$1:$1, 0))="","",INDEX('Airtable Input'!$A:$Z, 16, MATCH("Caption_EN", 'Airtable Input'!$1:$1, 0))&CHAR(10)&CHAR(10)&INDEX('Airtable Input'!$A:$Z, 16, MATCH("Hashtags_IG", 'Airtable Input'!$1:$1, 0))),"") | D16: =IFERROR(INDEX('Airtable Input'!$A:$Z, 16, MATCH("Image_URL", 'Airtable Input'!$1:$1, 0)),"") -> 0 | G16: =IFERROR(INDEX('Airtable Input'!$A:$Z, 16, MATCH("Headline_EN", 'Airtable Input'!$1:$1, 0)),"") -> 0 | H16: =IFERROR(IF(INDEX('Airtable Input'!$A:$Z, 16, MATCH("URL_Organic_UTM", 'Airtable Input'!$1:$1, 0))="","","🔗 Full details: "&INDEX('Airtable Input'!$A:$Z, 16, MATCH("URL_Organic_UTM", 'Airtable Input'!$1:$1, 0))),"") | I16: =IFERROR(IF(INDEX('Airtable Input'!$A:$Z, 16, MATCH("Format", 'Airtable Input'!$1:$1, 0))="Reel","Reel",IF(INDEX('Airtable Input'!$A:$Z, 16, MATCH("Format", 'Airtable Input'!$1:$1, 0))="Story","Story","")),"")
A17: =IFERROR(IF(INDEX('Airtable Input'!$A:$Z, 17, MATCH("Date", 'Airtable Input'!$1:$1, 0))="","",SUBSTITUTE(TEXT(INDEX('Airtable Input'!$A:$Z, 17, MATCH("Date", 'Airtable Input'!$1:$1, 0)),"YYYY-MM-DD"),"-","/")&" "&INDEX('Airtable Input'!$A:$Z, 17, MATCH("Time_NZST", 'Airtable Input'!$1:$1, 0))),"") | B17: =IFERROR(IF(INDEX('Airtable Input'!$A:$Z, 17, MATCH("Caption_EN", 'Airtable Input'!$1:$1, 0))="","",INDEX('Airtable Input'!$A:$Z, 17, MATCH("Caption_EN", 'Airtable Input'!$1:$1, 0))&CHAR(10)&CHAR(10)&INDEX('Airtable Input'!$A:$Z, 17, MATCH("Hashtags_IG", 'Airtable Input'!$1:$1, 0))),"") | D17: =IFERROR(INDEX('Airtable Input'!$A:$Z, 17, MATCH("Image_URL", 'Airtable Input'!$1:$1, 0)),"") -> 0 | G17: =IFERROR(INDEX('Airtable Input'!$A:$Z, 17, MATCH("Headline_EN", 'Airtable Input'!$1:$1, 0)),"") -> 0 | H17: =IFERROR(IF(INDEX('Airtable Input'!$A:$Z, 17, MATCH("URL_Organic_UTM", 'Airtable Input'!$1:$1, 0))="","","🔗 Full details: "&INDEX('Airtable Input'!$A:$Z, 17, MATCH("URL_Organic_UTM", 'Airtable Input'!$1:$1, 0))),"") | I17: =IFERROR(IF(INDEX('Airtable Input'!$A:$Z, 17, MATCH("Format", 'Airtable Input'!$1:$1, 0))="Reel","Reel",IF(INDEX('Airtable Input'!$A:$Z, 17, MATCH("Format", 'Airtable Input'!$1:$1, 0))="Story","Story","")),"")
A18: =IFERROR(IF(INDEX('Airtable Input'!$A:$Z, 18, MATCH("Date", 'Airtable Input'!$1:$1, 0))="","",SUBSTITUTE(TEXT(INDEX('Airtable Input'!$A:$Z, 18, MATCH("Date", 'Airtable Input'!$1:$1, 0)),"YYYY-MM-DD"),"-","/")&" "&INDEX('Airtable Input'!$A:$Z, 18, MATCH("Time_NZST", 'Airtable Input'!$1:$1, 0))),"") | B18: =IFERROR(IF(INDEX('Airtable Input'!$A:$Z, 18, MATCH("Caption_EN", 'Airtable Input'!$1:$1, 0))="","",INDEX('Airtable Input'!$A:$Z, 18, MATCH("Caption_EN", 'Airtable Input'!$1:$1, 0))&CHAR(10)&CHAR(10)&INDEX('Airtable Input'!$A:$Z, 18, MATCH("Hashtags_IG", 'Airtable Input'!$1:$1, 0))),"") | D18: =IFERROR(INDEX('Airtable Input'!$A:$Z, 18, MATCH("Image_URL", 'Airtable Input'!$1:$1, 0)),"") -> 0 | G18: =IFERROR(INDEX('Airtable Input'!$A:$Z, 18, MATCH("Headline_EN", 'Airtable Input'!$1:$1, 0)),"") -> 0 | H18: =IFERROR(IF(INDEX('Airtable Input'!$A:$Z, 18, MATCH("URL_Organic_UTM", 'Airtable Input'!$1:$1, 0))="","","🔗 Full details: "&INDEX('Airtable Input'!$A:$Z, 18, MATCH("URL_Organic_UTM", 'Airtable Input'!$1:$1, 0))),"") | I18: =IFERROR(IF(INDEX('Airtable Input'!$A:$Z, 18, MATCH("Format", 'Airtable Input'!$1:$1, 0))="Reel","Reel",IF(INDEX('Airtable Input'!$A:$Z, 18, MATCH("Format", 'Airtable Input'!$1:$1, 0))="Story","Story","")),"")
A19: =IFERROR(IF(INDEX('Airtable Input'!$A:$Z, 19, MATCH("Date", 'Airtable Input'!$1:$1, 0))="","",SUBSTITUTE(TEXT(INDEX('Airtable Input'!$A:$Z, 19, MATCH("Date", 'Airtable Input'!$1:$1, 0)),"YYYY-MM-DD"),"-","/")&" "&INDEX('Airtable Input'!$A:$Z, 19, MATCH("Time_NZST", 'Airtable Input'!$1:$1, 0))),"") | B19: =IFERROR(IF(INDEX('Airtable Input'!$A:$Z, 19, MATCH("Caption_EN", 'Airtable Input'!$1:$1, 0))="","",INDEX('Airtable Input'!$A:$Z, 19, MATCH("Caption_EN", 'Airtable Input'!$1:$1, 0))&CHAR(10)&CHAR(10)&INDEX('Airtable Input'!$A:$Z, 19, MATCH("Hashtags_IG", 'Airtable Input'!$1:$1, 0))),"") | D19: =IFERROR(INDEX('Airtable Input'!$A:$Z, 19, MATCH("Image_URL", 'Airtable Input'!$1:$1, 0)),"") -> 0 | G19: =IFERROR(INDEX('Airtable Input'!$A:$Z, 19, MATCH("Headline_EN", 'Airtable Input'!$1:$1, 0)),"") -> 0 | H19: =IFERROR(IF(INDEX('Airtable Input'!$A:$Z, 19, MATCH("URL_Organic_UTM", 'Airtable Input'!$1:$1, 0))="","","🔗 Full details: "&INDEX('Airtable Input'!$A:$Z, 19, MATCH("URL_Organic_UTM", 'Airtable Input'!$1:$1, 0))),"") | I19: =IFERROR(IF(INDEX('Airtable Input'!$A:$Z, 19, MATCH("Format", 'Airtable Input'!$1:$1, 0))="Reel","Reel",IF(INDEX('Airtable Input'!$A:$Z, 19, MATCH("Format", 'Airtable Input'!$1:$1, 0))="Story","Story","")),"")
A20: =IFERROR(IF(INDEX('Airtable Input'!$A:$Z, 20, MATCH("Date", 'Airtable Input'!$1:$1, 0))="","",SUBSTITUTE(TEXT(INDEX('Airtable Input'!$A:$Z, 20, MATCH("Date", 'Airtable Input'!$1:$1, 0)),"YYYY-MM-DD"),"-","/")&" "&INDEX('Airtable Input'!$A:$Z, 20, MATCH("Time_NZST", 'Airtable Input'!$1:$1, 0))),"") | B20: =IFERROR(IF(INDEX('Airtable Input'!$A:$Z, 20, MATCH("Caption_EN", 'Airtable Input'!$1:$1, 0))="","",INDEX('Airtable Input'!$A:$Z, 20, MATCH("Caption_EN", 'Airtable Input'!$1:$1, 0))&CHAR(10)&CHAR(10)&INDEX('Airtable Input'!$A:$Z, 20, MATCH("Hashtags_IG", 'Airtable Input'!$1:$1, 0))),"") | D20: =IFERROR(INDEX('Airtable Input'!$A:$Z, 20, MATCH("Image_URL", 'Airtable Input'!$1:$1, 0)),"") -> 0 | G20: =IFERROR(INDEX('Airtable Input'!$A:$Z, 20, MATCH("Headline_EN", 'Airtable Input'!$1:$1, 0)),"") -> 0 | H20: =IFERROR(IF(INDEX('Airtable Input'!$A:$Z, 20, MATCH("URL_Organic_UTM", 'Airtable Input'!$1:$1, 0))="","","🔗 Full details: "&INDEX('Airtable Input'!$A:$Z, 20, MATCH("URL_Organic_UTM", 'Airtable Input'!$1:$1, 0))),"") | I20: =IFERROR(IF(INDEX('Airtable Input'!$A:$Z, 20, MATCH("Format", 'Airtable Input'!$1:$1, 0))="Reel","Reel",IF(INDEX('Airtable Input'!$A:$Z, 20, MATCH("Format", 'Airtable Input'!$1:$1, 0))="Story","Story","")),"")
A21: =IFERROR(IF(INDEX('Airtable Input'!$A:$Z, 21, MATCH("Date", 'Airtable Input'!$1:$1, 0))="","",SUBSTITUTE(TEXT(INDEX('Airtable Input'!$A:$Z, 21, MATCH("Date", 'Airtable Input'!$1:$1, 0)),"YYYY-MM-DD"),"-","/")&" "&INDEX('Airtable Input'!$A:$Z, 21, MATCH("Time_NZST", 'Airtable Input'!$1:$1, 0))),"") | B21: =IFERROR(IF(INDEX('Airtable Input'!$A:$Z, 21, MATCH("Caption_EN", 'Airtable Input'!$1:$1, 0))="","",INDEX('Airtable Input'!$A:$Z, 21, MATCH("Caption_EN", 'Airtable Input'!$1:$1, 0))&CHAR(10)&CHAR(10)&INDEX('Airtable Input'!$A:$Z, 21, MATCH("Hashtags_IG", 'Airtable Input'!$1:$1, 0))),"") | D21: =IFERROR(INDEX('Airtable Input'!$A:$Z, 21, MATCH("Image_URL", 'Airtable Input'!$1:$1, 0)),"") -> 0 | G21: =IFERROR(INDEX('Airtable Input'!$A:$Z, 21, MATCH("Headline_EN", 'Airtable Input'!$1:$1, 0)),"") -> 0 | H21: =IFERROR(IF(INDEX('Airtable Input'!$A:$Z, 21, MATCH("URL_Organic_UTM", 'Airtable Input'!$1:$1, 0))="","","🔗 Full details: "&INDEX('Airtable Input'!$A:$Z, 21, MATCH("URL_Organic_UTM", 'Airtable Input'!$1:$1, 0))),"") | I21: =IFERROR(IF(INDEX('Airtable Input'!$A:$Z, 21, MATCH("Format", 'Airtable Input'!$1:$1, 0))="Reel","Reel",IF(INDEX('Airtable Input'!$A:$Z, 21, MATCH("Format", 'Airtable Input'!$1:$1, 0))="Story","Story","")),"")
A22: =IFERROR(IF(INDEX('Airtable Input'!$A:$Z, 22, MATCH("Date", 'Airtable Input'!$1:$1, 0))="","",SUBSTITUTE(TEXT(INDEX('Airtable Input'!$A:$Z, 22, MATCH("Date", 'Airtable Input'!$1:$1, 0)),"YYYY-MM-DD"),"-","/")&" "&INDEX('Airtable Input'!$A:$Z, 22, MATCH("Time_NZST", 'Airtable Input'!$1:$1, 0))),"") | B22: =IFERROR(IF(INDEX('Airtable Input'!$A:$Z, 22, MATCH("Caption_EN", 'Airtable Input'!$1:$1, 0))="","",INDEX('Airtable Input'!$A:$Z, 22, MATCH("Caption_EN", 'Airtable Input'!$1:$1, 0))&CHAR(10)&CHAR(10)&INDEX('Airtable Input'!$A:$Z, 22, MATCH("Hashtags_IG", 'Airtable Input'!$1:$1, 0))),"") | D22: =IFERROR(INDEX('Airtable Input'!$A:$Z, 22, MATCH("Image_URL", 'Airtable Input'!$1:$1, 0)),"") -> 0 | G22: =IFERROR(INDEX('Airtable Input'!$A:$Z, 22, MATCH("Headline_EN", 'Airtable Input'!$1:$1, 0)),"") -> 0 | H22: =IFERROR(IF(INDEX('Airtable Input'!$A:$Z, 22, MATCH("URL_Organic_UTM", 'Airtable Input'!$1:$1, 0))="","","🔗 Full details: "&INDEX('Airtable Input'!$A:$Z, 22, MATCH("URL_Organic_UTM", 'Airtable Input'!$1:$1, 0))),"") | I22: =IFERROR(IF(INDEX('Airtable Input'!$A:$Z, 22, MATCH("Format", 'Airtable Input'!$1:$1, 0))="Reel","Reel",IF(INDEX('Airtable Input'!$A:$Z, 22, MATCH("Format", 'Airtable Input'!$1:$1, 0))="Story","Story","")),"")
A23: =IFERROR(IF(INDEX('Airtable Input'!$A:$Z, 23, MATCH("Date", 'Airtable Input'!$1:$1, 0))="","",SUBSTITUTE(TEXT(INDEX('Airtable Input'!$A:$Z, 23, MATCH("Date", 'Airtable Input'!$1:$1, 0)),"YYYY-MM-DD"),"-","/")&" "&INDEX('Airtable Input'!$A:$Z, 23, MATCH("Time_NZST", 'Airtable Input'!$1:$1, 0))),"") | B23: =IFERROR(IF(INDEX('Airtable Input'!$A:$Z, 23, MATCH("Caption_EN", 'Airtable Input'!$1:$1, 0))="","",INDEX('Airtable Input'!$A:$Z, 23, MATCH("Caption_EN", 'Airtable Input'!$1:$1, 0))&CHAR(10)&CHAR(10)&INDEX('Airtable Input'!$A:$Z, 23, MATCH("Hashtags_IG", 'Airtable Input'!$1:$1, 0))),"") | D23: =IFERROR(INDEX('Airtable Input'!$A:$Z, 23, MATCH("Image_URL", 'Airtable Input'!$1:$1, 0)),"") -> 0 | G23: =IFERROR(INDEX('Airtable Input'!$A:$Z, 23, MATCH("Headline_EN", 'Airtable Input'!$1:$1, 0)),"") -> 0 | H23: =IFERROR(IF(INDEX('Airtable Input'!$A:$Z, 23, MATCH("URL_Organic_UTM", 'Airtable Input'!$1:$1, 0))="","","🔗 Full details: "&INDEX('Airtable Input'!$A:$Z, 23, MATCH("URL_Organic_UTM", 'Airtable Input'!$1:$1, 0))),"") | I23: =IFERROR(IF(INDEX('Airtable Input'!$A:$Z, 23, MATCH("Format", 'Airtable Input'!$1:$1, 0))="Reel","Reel",IF(INDEX('Airtable Input'!$A:$Z, 23, MATCH("Format", 'Airtable Input'!$1:$1, 0))="Story","Story","")),"")
A24: =IFERROR(IF(INDEX('Airtable Input'!$A:$Z, 24, MATCH("Date", 'Airtable Input'!$1:$1, 0))="","",SUBSTITUTE(TEXT(INDEX('Airtable Input'!$A:$Z, 24, MATCH("Date", 'Airtable Input'!$1:$1, 0)),"YYYY-MM-DD"),"-","/")&" "&INDEX('Airtable Input'!$A:$Z, 24, MATCH("Time_NZST", 'Airtable Input'!$1:$1, 0))),"") | B24: =IFERROR(IF(INDEX('Airtable Input'!$A:$Z, 24, MATCH("Caption_EN", 'Airtable Input'!$1:$1, 0))="","",INDEX('Airtable Input'!$A:$Z, 24, MATCH("Caption_EN", 'Airtable Input'!$1:$1, 0))&CHAR(10)&CHAR(10)&INDEX('Airtable Input'!$A:$Z, 24, MATCH("Hashtags_IG", 'Airtable Input'!$1:$1, 0))),"") | D24: =IFERROR(INDEX('Airtable Input'!$A:$Z, 24, MATCH("Image_URL", 'Airtable Input'!$1:$1, 0)),"") -> 0 | G24: =IFERROR(INDEX('Airtable Input'!$A:$Z, 24, MATCH("Headline_EN", 'Airtable Input'!$1:$1, 0)),"") -> 0 | H24: =IFERROR(IF(INDEX('Airtable Input'!$A:$Z, 24, MATCH("URL_Organic_UTM", 'Airtable Input'!$1:$1, 0))="","","🔗 Full details: "&INDEX('Airtable Input'!$A:$Z, 24, MATCH("URL_Organic_UTM", 'Airtable Input'!$1:$1, 0))),"") | I24: =IFERROR(IF(INDEX('Airtable Input'!$A:$Z, 24, MATCH("Format", 'Airtable Input'!$1:$1, 0))="Reel","Reel",IF(INDEX('Airtable Input'!$A:$Z, 24, MATCH("Format", 'Airtable Input'!$1:$1, 0))="Story","Story","")),"")
A25: =IFERROR(IF(INDEX('Airtable Input'!$A:$Z, 25, MATCH("Date", 'Airtable Input'!$1:$1, 0))="","",SUBSTITUTE(TEXT(INDEX('Airtable Input'!$A:$Z, 25, MATCH("Date", 'Airtable Input'!$1:$1, 0)),"YYYY-MM-DD"),"-","/")&" "&INDEX('Airtable Input'!$A:$Z, 25, MATCH("Time_NZST", 'Airtable Input'!$1:$1, 0))),"") | B25: =IFERROR(IF(INDEX('Airtable Input'!$A:$Z, 25, MATCH("Caption_EN", 'Airtable Input'!$1:$1, 0))="","",INDEX('Airtable Input'!$A:$Z, 25, MATCH("Caption_EN", 'Airtable Input'!$1:$1, 0))&CHAR(10)&CHAR(10)&INDEX('Airtable Input'!$A:$Z, 25, MATCH("Hashtags_IG", 'Airtable Input'!$1:$1, 0))),"") | D25: =IFERROR(INDEX('Airtable Input'!$A:$Z, 25, MATCH("Image_URL", 'Airtable Input'!$1:$1, 0)),"") -> 0 | G25: =IFERROR(INDEX('Airtable Input'!$A:$Z, 25, MATCH("Headline_EN", 'Airtable Input'!$1:$1, 0)),"") -> 0 | H25: =IFERROR(IF(INDEX('Airtable Input'!$A:$Z, 25, MATCH("URL_Organic_UTM", 'Airtable Input'!$1:$1, 0))="","","🔗 Full details: "&INDEX('Airtable Input'!$A:$Z, 25, MATCH("URL_Organic_UTM", 'Airtable Input'!$1:$1, 0))),"") | I25: =IFERROR(IF(INDEX('Airtable Input'!$A:$Z, 25, MATCH("Format", 'Airtable Input'!$1:$1, 0))="Reel","Reel",IF(INDEX('Airtable Input'!$A:$Z, 25, MATCH("Format", 'Airtable Input'!$1:$1, 0))="Story","Story","")),"")
A26: =IFERROR(IF(INDEX('Airtable Input'!$A:$Z, 26, MATCH("Date", 'Airtable Input'!$1:$1, 0))="","",SUBSTITUTE(TEXT(INDEX('Airtable Input'!$A:$Z, 26, MATCH("Date", 'Airtable Input'!$1:$1, 0)),"YYYY-MM-DD"),"-","/")&" "&INDEX('Airtable Input'!$A:$Z, 26, MATCH("Time_NZST", 'Airtable Input'!$1:$1, 0))),"") | B26: =IFERROR(IF(INDEX('Airtable Input'!$A:$Z, 26, MATCH("Caption_EN", 'Airtable Input'!$1:$1, 0))="","",INDEX('Airtable Input'!$A:$Z, 26, MATCH("Caption_EN", 'Airtable Input'!$1:$1, 0))&CHAR(10)&CHAR(10)&INDEX('Airtable Input'!$A:$Z, 26, MATCH("Hashtags_IG", 'Airtable Input'!$1:$1, 0))),"") | D26: =IFERROR(INDEX('Airtable Input'!$A:$Z, 26, MATCH("Image_URL", 'Airtable Input'!$1:$1, 0)),"") -> 0 | G26: =IFERROR(INDEX('Airtable Input'!$A:$Z, 26, MATCH("Headline_EN", 'Airtable Input'!$1:$1, 0)),"") -> 0 | H26: =IFERROR(IF(INDEX('Airtable Input'!$A:$Z, 26, MATCH("URL_Organic_UTM", 'Airtable Input'!$1:$1, 0))="","","🔗 Full details: "&INDEX('Airtable Input'!$A:$Z, 26, MATCH("URL_Organic_UTM", 'Airtable Input'!$1:$1, 0))),"") | I26: =IFERROR(IF(INDEX('Airtable Input'!$A:$Z, 26, MATCH("Format", 'Airtable Input'!$1:$1, 0))="Reel","Reel",IF(INDEX('Airtable Input'!$A:$Z, 26, MATCH("Format", 'Airtable Input'!$1:$1, 0))="Story","Story","")),"")
A27: =IFERROR(IF(INDEX('Airtable Input'!$A:$Z, 27, MATCH("Date", 'Airtable Input'!$1:$1, 0))="","",SUBSTITUTE(TEXT(INDEX('Airtable Input'!$A:$Z, 27, MATCH("Date", 'Airtable Input'!$1:$1, 0)),"YYYY-MM-DD"),"-","/")&" "&INDEX('Airtable Input'!$A:$Z, 27, MATCH("Time_NZST", 'Airtable Input'!$1:$1, 0))),"") | B27: =IFERROR(IF(INDEX('Airtable Input'!$A:$Z, 27, MATCH("Caption_EN", 'Airtable Input'!$1:$1, 0))="","",INDEX('Airtable Input'!$A:$Z, 27, MATCH("Caption_EN", 'Airtable Input'!$1:$1, 0))&CHAR(10)&CHAR(10)&INDEX('Airtable Input'!$A:$Z, 27, MATCH("Hashtags_IG", 'Airtable Input'!$1:$1, 0))),"") | D27: =IFERROR(INDEX('Airtable Input'!$A:$Z, 27, MATCH("Image_URL", 'Airtable Input'!$1:$1, 0)),"") -> 0 | G27: =IFERROR(INDEX('Airtable Input'!$A:$Z, 27, MATCH("Headline_EN", 'Airtable Input'!$1:$1, 0)),"") -> 0 | H27: =IFERROR(IF(INDEX('Airtable Input'!$A:$Z, 27, MATCH("URL_Organic_UTM", 'Airtable Input'!$1:$1, 0))="","","🔗 Full details: "&INDEX('Airtable Input'!$A:$Z, 27, MATCH("URL_Organic_UTM", 'Airtable Input'!$1:$1, 0))),"") | I27: =IFERROR(IF(INDEX('Airtable Input'!$A:$Z, 27, MATCH("Format", 'Airtable Input'!$1:$1, 0))="Reel","Reel",IF(INDEX('Airtable Input'!$A:$Z, 27, MATCH("Format", 'Airtable Input'!$1:$1, 0))="Story","Story","")),"")
A28: =IFERROR(IF(INDEX('Airtable Input'!$A:$Z, 28, MATCH("Date", 'Airtable Input'!$1:$1, 0))="","",SUBSTITUTE(TEXT(INDEX('Airtable Input'!$A:$Z, 28, MATCH("Date", 'Airtable Input'!$1:$1, 0)),"YYYY-MM-DD"),"-","/")&" "&INDEX('Airtable Input'!$A:$Z, 28, MATCH("Time_NZST", 'Airtable Input'!$1:$1, 0))),"") | B28: =IFERROR(IF(INDEX('Airtable Input'!$A:$Z, 28, MATCH("Caption_EN", 'Airtable Input'!$1:$1, 0))="","",INDEX('Airtable Input'!$A:$Z, 28, MATCH("Caption_EN", 'Airtable Input'!$1:$1, 0))&CHAR(10)&CHAR(10)&INDEX('Airtable Input'!$A:$Z, 28, MATCH("Hashtags_IG", 'Airtable Input'!$1:$1, 0))),"") | D28: =IFERROR(INDEX('Airtable Input'!$A:$Z, 28, MATCH("Image_URL", 'Airtable Input'!$1:$1, 0)),"") -> 0 | G28: =IFERROR(INDEX('Airtable Input'!$A:$Z, 28, MATCH("Headline_EN", 'Airtable Input'!$1:$1, 0)),"") -> 0 | H28: =IFERROR(IF(INDEX('Airtable Input'!$A:$Z, 28, MATCH("URL_Organic_UTM", 'Airtable Input'!$1:$1, 0))="","","🔗 Full details: "&INDEX('Airtable Input'!$A:$Z, 28, MATCH("URL_Organic_UTM", 'Airtable Input'!$1:$1, 0))),"") | I28: =IFERROR(IF(INDEX('Airtable Input'!$A:$Z, 28, MATCH("Format", 'Airtable Input'!$1:$1, 0))="Reel","Reel",IF(INDEX('Airtable Input'!$A:$Z, 28, MATCH("Format", 'Airtable Input'!$1:$1, 0))="Story","Story","")),"")
A29: =IFERROR(IF(INDEX('Airtable Input'!$A:$Z, 29, MATCH("Date", 'Airtable Input'!$1:$1, 0))="","",SUBSTITUTE(TEXT(INDEX('Airtable Input'!$A:$Z, 29, MATCH("Date", 'Airtable Input'!$1:$1, 0)),"YYYY-MM-DD"),"-","/")&" "&INDEX('Airtable Input'!$A:$Z, 29, MATCH("Time_NZST", 'Airtable Input'!$1:$1, 0))),"") | B29: =IFERROR(IF(INDEX('Airtable Input'!$A:$Z, 29, MATCH("Caption_EN", 'Airtable Input'!$1:$1, 0))="","",INDEX('Airtable Input'!$A:$Z, 29, MATCH("Caption_EN", 'Airtable Input'!$1:$1, 0))&CHAR(10)&CHAR(10)&INDEX('Airtable Input'!$A:$Z, 29, MATCH("Hashtags_IG", 'Airtable Input'!$1:$1, 0))),"") | D29: =IFERROR(INDEX('Airtable Input'!$A:$Z, 29, MATCH("Image_URL", 'Airtable Input'!$1:$1, 0)),"") -> 0 | G29: =IFERROR(INDEX('Airtable Input'!$A:$Z, 29, MATCH("Headline_EN", 'Airtable Input'!$1:$1, 0)),"") -> 0 | H29: =IFERROR(IF(INDEX('Airtable Input'!$A:$Z, 29, MATCH("URL_Organic_UTM", 'Airtable Input'!$1:$1, 0))="","","🔗 Full details: "&INDEX('Airtable Input'!$A:$Z, 29, MATCH("URL_Organic_UTM", 'Airtable Input'!$1:$1, 0))),"") | I29: =IFERROR(IF(INDEX('Airtable Input'!$A:$Z, 29, MATCH("Format", 'Airtable Input'!$1:$1, 0))="Reel","Reel",IF(INDEX('Airtable Input'!$A:$Z, 29, MATCH("Format", 'Airtable Input'!$1:$1, 0))="Story","Story","")),"")
A30: =IFERROR(IF(INDEX('Airtable Input'!$A:$Z, 30, MATCH("Date", 'Airtable Input'!$1:$1, 0))="","",SUBSTITUTE(TEXT(INDEX('Airtable Input'!$A:$Z, 30, MATCH("Date", 'Airtable Input'!$1:$1, 0)),"YYYY-MM-DD"),"-","/")&" "&INDEX('Airtable Input'!$A:$Z, 30, MATCH("Time_NZST", 'Airtable Input'!$1:$1, 0))),"") | B30: =IFERROR(IF(INDEX('Airtable Input'!$A:$Z, 30, MATCH("Caption_EN", 'Airtable Input'!$1:$1, 0))="","",INDEX('Airtable Input'!$A:$Z, 30, MATCH("Caption_EN", 'Airtable Input'!$1:$1, 0))&CHAR(10)&CHAR(10)&INDEX('Airtable Input'!$A:$Z, 30, MATCH("Hashtags_IG", 'Airtable Input'!$1:$1, 0))),"") | D30: =IFERROR(INDEX('Airtable Input'!$A:$Z, 30, MATCH("Image_URL", 'Airtable Input'!$1:$1, 0)),"") -> 0 | G30: =IFERROR(INDEX('Airtable Input'!$A:$Z, 30, MATCH("Headline_EN", 'Airtable Input'!$1:$1, 0)),"") -> 0 | H30: =IFERROR(IF(INDEX('Airtable Input'!$A:$Z, 30, MATCH("URL_Organic_UTM", 'Airtable Input'!$1:$1, 0))="","","🔗 Full details: "&INDEX('Airtable Input'!$A:$Z, 30, MATCH("URL_Organic_UTM", 'Airtable Input'!$1:$1, 0))),"") | I30: =IFERROR(IF(INDEX('Airtable Input'!$A:$Z, 30, MATCH("Format", 'Airtable Input'!$1:$1, 0))="Reel","Reel",IF(INDEX('Airtable Input'!$A:$Z, 30, MATCH("Format", 'Airtable Input'!$1:$1, 0))="Story","Story","")),"")
A31: =IFERROR(IF(INDEX('Airtable Input'!$A:$Z, 31, MATCH("Date", 'Airtable Input'!$1:$1, 0))="","",SUBSTITUTE(TEXT(INDEX('Airtable Input'!$A:$Z, 31, MATCH("Date", 'Airtable Input'!$1:$1, 0)),"YYYY-MM-DD"),"-","/")&" "&INDEX('Airtable Input'!$A:$Z, 31, MATCH("Time_NZST", 'Airtable Input'!$1:$1, 0))),"") | B31: =IFERROR(IF(INDEX('Airtable Input'!$A:$Z, 31, MATCH("Caption_EN", 'Airtable Input'!$1:$1, 0))="","",INDEX('Airtable Input'!$A:$Z, 31, MATCH("Caption_EN", 'Airtable Input'!$1:$1, 0))&CHAR(10)&CHAR(10)&INDEX('Airtable Input'!$A:$Z, 31, MATCH("Hashtags_IG", 'Airtable Input'!$1:$1, 0))),"") | D31: =IFERROR(INDEX('Airtable Input'!$A:$Z, 31, MATCH("Image_URL", 'Airtable Input'!$1:$1, 0)),"") -> 0 | G31: =IFERROR(INDEX('Airtable Input'!$A:$Z, 31, MATCH("Headline_EN", 'Airtable Input'!$1:$1, 0)),"") -> 0 | H31: =IFERROR(IF(INDEX('Airtable Input'!$A:$Z, 31, MATCH("URL_Organic_UTM", 'Airtable Input'!$1:$1, 0))="","","🔗 Full details: "&INDEX('Airtable Input'!$A:$Z, 31, MATCH("URL_Organic_UTM", 'Airtable Input'!$1:$1, 0))),"") | I31: =IFERROR(IF(INDEX('Airtable Input'!$A:$Z, 31, MATCH("Format", 'Airtable Input'!$1:$1, 0))="Reel","Reel",IF(INDEX('Airtable Input'!$A:$Z, 31, MATCH("Format", 'Airtable Input'!$1:$1, 0))="Story","Story","")),"")
A32: =IFERROR(IF(INDEX('Airtable Input'!$A:$Z, 32, MATCH("Date", 'Airtable Input'!$1:$1, 0))="","",SUBSTITUTE(TEXT(INDEX('Airtable Input'!$A:$Z, 32, MATCH("Date", 'Airtable Input'!$1:$1, 0)),"YYYY-MM-DD"),"-","/")&" "&INDEX('Airtable Input'!$A:$Z, 32, MATCH("Time_NZST", 'Airtable Input'!$1:$1, 0))),"") | B32: =IFERROR(IF(INDEX('Airtable Input'!$A:$Z, 32, MATCH("Caption_EN", 'Airtable Input'!$1:$1, 0))="","",INDEX('Airtable Input'!$A:$Z, 32, MATCH("Caption_EN", 'Airtable Input'!$1:$1, 0))&CHAR(10)&CHAR(10)&INDEX('Airtable Input'!$A:$Z, 32, MATCH("Hashtags_IG", 'Airtable Input'!$1:$1, 0))),"") | D32: =IFERROR(INDEX('Airtable Input'!$A:$Z, 32, MATCH("Image_URL", 'Airtable Input'!$1:$1, 0)),"") -> 0 | G32: =IFERROR(INDEX('Airtable Input'!$A:$Z, 32, MATCH("Headline_EN", 'Airtable Input'!$1:$1, 0)),"") -> 0 | H32: =IFERROR(IF(INDEX('Airtable Input'!$A:$Z, 32, MATCH("URL_Organic_UTM", 'Airtable Input'!$1:$1, 0))="","","🔗 Full details: "&INDEX('Airtable Input'!$A:$Z, 32, MATCH("URL_Organic_UTM", 'Airtable Input'!$1:$1, 0))),"") | I32: =IFERROR(IF(INDEX('Airtable Input'!$A:$Z, 32, MATCH("Format", 'Airtable Input'!$1:$1, 0))="Reel","Reel",IF(INDEX('Airtable Input'!$A:$Z, 32, MATCH("Format", 'Airtable Input'!$1:$1, 0))="Story","Story","")),"")
A33: =IFERROR(IF(INDEX('Airtable Input'!$A:$Z, 33, MATCH("Date", 'Airtable Input'!$1:$1, 0))="","",SUBSTITUTE(TEXT(INDEX('Airtable Input'!$A:$Z, 33, MATCH("Date", 'Airtable Input'!$1:$1, 0)),"YYYY-MM-DD"),"-","/")&" "&INDEX('Airtable Input'!$A:$Z, 33, MATCH("Time_NZST", 'Airtable Input'!$1:$1, 0))),"") | B33: =IFERROR(IF(INDEX('Airtable Input'!$A:$Z, 33, MATCH("Caption_EN", 'Airtable Input'!$1:$1, 0))="","",INDEX('Airtable Input'!$A:$Z, 33, MATCH("Caption_EN", 'Airtable Input'!$1:$1, 0))&CHAR(10)&CHAR(10)&INDEX('Airtable Input'!$A:$Z, 33, MATCH("Hashtags_IG", 'Airtable Input'!$1:$1, 0))),"") | D33: =IFERROR(INDEX('Airtable Input'!$A:$Z, 33, MATCH("Image_URL", 'Airtable Input'!$1:$1, 0)),"") -> 0 | G33: =IFERROR(INDEX('Airtable Input'!$A:$Z, 33, MATCH("Headline_EN", 'Airtable Input'!$1:$1, 0)),"") -> 0 | H33: =IFERROR(IF(INDEX('Airtable Input'!$A:$Z, 33, MATCH("URL_Organic_UTM", 'Airtable Input'!$1:$1, 0))="","","🔗 Full details: "&INDEX('Airtable Input'!$A:$Z, 33, MATCH("URL_Organic_UTM", 'Airtable Input'!$1:$1, 0))),"") | I33: =IFERROR(IF(INDEX('Airtable Input'!$A:$Z, 33, MATCH("Format", 'Airtable Input'!$1:$1, 0))="Reel","Reel",IF(INDEX('Airtable Input'!$A:$Z, 33, MATCH("Format", 'Airtable Input'!$1:$1, 0))="Story","Story","")),"")
A34: =IFERROR(IF(INDEX('Airtable Input'!$A:$Z, 34, MATCH("Date", 'Airtable Input'!$1:$1, 0))="","",SUBSTITUTE(TEXT(INDEX('Airtable Input'!$A:$Z, 34, MATCH("Date", 'Airtable Input'!$1:$1, 0)),"YYYY-MM-DD"),"-","/")&" "&INDEX('Airtable Input'!$A:$Z, 34, MATCH("Time_NZST", 'Airtable Input'!$1:$1, 0))),"") | B34: =IFERROR(IF(INDEX('Airtable Input'!$A:$Z, 34, MATCH("Caption_EN", 'Airtable Input'!$1:$1, 0))="","",INDEX('Airtable Input'!$A:$Z, 34, MATCH("Caption_EN", 'Airtable Input'!$1:$1, 0))&CHAR(10)&CHAR(10)&INDEX('Airtable Input'!$A:$Z, 34, MATCH("Hashtags_IG", 'Airtable Input'!$1:$1, 0))),"") | D34: =IFERROR(INDEX('Airtable Input'!$A:$Z, 34, MATCH("Image_URL", 'Airtable Input'!$1:$1, 0)),"") -> 0 | G34: =IFERROR(INDEX('Airtable Input'!$A:$Z, 34, MATCH("Headline_EN", 'Airtable Input'!$1:$1, 0)),"") -> 0 | H34: =IFERROR(IF(INDEX('Airtable Input'!$A:$Z, 34, MATCH("URL_Organic_UTM", 'Airtable Input'!$1:$1, 0))="","","🔗 Full details: "&INDEX('Airtable Input'!$A:$Z, 34, MATCH("URL_Organic_UTM", 'Airtable Input'!$1:$1, 0))),"") | I34: =IFERROR(IF(INDEX('Airtable Input'!$A:$Z, 34, MATCH("Format", 'Airtable Input'!$1:$1, 0))="Reel","Reel",IF(INDEX('Airtable Input'!$A:$Z, 34, MATCH("Format", 'Airtable Input'!$1:$1, 0))="Story","Story","")),"")
A35: =IFERROR(IF(INDEX('Airtable Input'!$A:$Z, 35, MATCH("Date", 'Airtable Input'!$1:$1, 0))="","",SUBSTITUTE(TEXT(INDEX('Airtable Input'!$A:$Z, 35, MATCH("Date", 'Airtable Input'!$1:$1, 0)),"YYYY-MM-DD"),"-","/")&" "&INDEX('Airtable Input'!$A:$Z, 35, MATCH("Time_NZST", 'Airtable Input'!$1:$1, 0))),"") | B35: =IFERROR(IF(INDEX('Airtable Input'!$A:$Z, 35, MATCH("Caption_EN", 'Airtable Input'!$1:$1, 0))="","",INDEX('Airtable Input'!$A:$Z, 35, MATCH("Caption_EN", 'Airtable Input'!$1:$1, 0))&CHAR(10)&CHAR(10)&INDEX('Airtable Input'!$A:$Z, 35, MATCH("Hashtags_IG", 'Airtable Input'!$1:$1, 0))),"") | D35: =IFERROR(INDEX('Airtable Input'!$A:$Z, 35, MATCH("Image_URL", 'Airtable Input'!$1:$1, 0)),"") -> 0 | G35: =IFERROR(INDEX('Airtable Input'!$A:$Z, 35, MATCH("Headline_EN", 'Airtable Input'!$1:$1, 0)),"") -> 0 | H35: =IFERROR(IF(INDEX('Airtable Input'!$A:$Z, 35, MATCH("URL_Organic_UTM", 'Airtable Input'!$1:$1, 0))="","","🔗 Full details: "&INDEX('Airtable Input'!$A:$Z, 35, MATCH("URL_Organic_UTM", 'Airtable Input'!$1:$1, 0))),"") | I35: =IFERROR(IF(INDEX('Airtable Input'!$A:$Z, 35, MATCH("Format", 'Airtable Input'!$1:$1, 0))="Reel","Reel",IF(INDEX('Airtable Input'!$A:$Z, 35, MATCH("Format", 'Airtable Input'!$1:$1, 0))="Story","Story","")),"")
A36: =IFERROR(IF(INDEX('Airtable Input'!$A:$Z, 36, MATCH("Date", 'Airtable Input'!$1:$1, 0))="","",SUBSTITUTE(TEXT(INDEX('Airtable Input'!$A:$Z, 36, MATCH("Date", 'Airtable Input'!$1:$1, 0)),"YYYY-MM-DD"),"-","/")&" "&INDEX('Airtable Input'!$A:$Z, 36, MATCH("Time_NZST", 'Airtable Input'!$1:$1, 0))),"") | B36: =IFERROR(IF(INDEX('Airtable Input'!$A:$Z, 36, MATCH("Caption_EN", 'Airtable Input'!$1:$1, 0))="","",INDEX('Airtable Input'!$A:$Z, 36, MATCH("Caption_EN", 'Airtable Input'!$1:$1, 0))&CHAR(10)&CHAR(10)&INDEX('Airtable Input'!$A:$Z, 36, MATCH("Hashtags_IG", 'Airtable Input'!$1:$1, 0))),"") | D36: =IFERROR(INDEX('Airtable Input'!$A:$Z, 36, MATCH("Image_URL", 'Airtable Input'!$1:$1, 0)),"") -> 0 | G36: =IFERROR(INDEX('Airtable Input'!$A:$Z, 36, MATCH("Headline_EN", 'Airtable Input'!$1:$1, 0)),"") -> 0 | H36: =IFERROR(IF(INDEX('Airtable Input'!$A:$Z, 36, MATCH("URL_Organic_UTM", 'Airtable Input'!$1:$1, 0))="","","🔗 Full details: "&INDEX('Airtable Input'!$A:$Z, 36, MATCH("URL_Organic_UTM", 'Airtable Input'!$1:$1, 0))),"") | I36: =IFERROR(IF(INDEX('Airtable Input'!$A:$Z, 36, MATCH("Format", 'Airtable Input'!$1:$1, 0))="Reel","Reel",IF(INDEX('Airtable Input'!$A:$Z, 36, MATCH("Format", 'Airtable Input'!$1:$1, 0))="Story","Story","")),"")
A37: =IFERROR(IF(INDEX('Airtable Input'!$A:$Z, 37, MATCH("Date", 'Airtable Input'!$1:$1, 0))="","",SUBSTITUTE(TEXT(INDEX('Airtable Input'!$A:$Z, 37, MATCH("Date", 'Airtable Input'!$1:$1, 0)),"YYYY-MM-DD"),"-","/")&" "&INDEX('Airtable Input'!$A:$Z, 37, MATCH("Time_NZST", 'Airtable Input'!$1:$1, 0))),"") | B37: =IFERROR(IF(INDEX('Airtable Input'!$A:$Z, 37, MATCH("Caption_EN", 'Airtable Input'!$1:$1, 0))="","",INDEX('Airtable Input'!$A:$Z, 37, MATCH("Caption_EN", 'Airtable Input'!$1:$1, 0))&CHAR(10)&CHAR(10)&INDEX('Airtable Input'!$A:$Z, 37, MATCH("Hashtags_IG", 'Airtable Input'!$1:$1, 0))),"") | D37: =IFERROR(INDEX('Airtable Input'!$A:$Z, 37, MATCH("Image_URL", 'Airtable Input'!$1:$1, 0)),"") -> 0 | G37: =IFERROR(INDEX('Airtable Input'!$A:$Z, 37, MATCH("Headline_EN", 'Airtable Input'!$1:$1, 0)),"") -> 0 | H37: =IFERROR(IF(INDEX('Airtable Input'!$A:$Z, 37, MATCH("URL_Organic_UTM", 'Airtable Input'!$1:$1, 0))="","","🔗 Full details: "&INDEX('Airtable Input'!$A:$Z, 37, MATCH("URL_Organic_UTM", 'Airtable Input'!$1:$1, 0))),"") | I37: =IFERROR(IF(INDEX('Airtable Input'!$A:$Z, 37, MATCH("Format", 'Airtable Input'!$1:$1, 0))="Reel","Reel",IF(INDEX('Airtable Input'!$A:$Z, 37, MATCH("Format", 'Airtable Input'!$1:$1, 0))="Story","Story","")),"")
A38: =IFERROR(IF(INDEX('Airtable Input'!$A:$Z, 38, MATCH("Date", 'Airtable Input'!$1:$1, 0))="","",SUBSTITUTE(TEXT(INDEX('Airtable Input'!$A:$Z, 38, MATCH("Date", 'Airtable Input'!$1:$1, 0)),"YYYY-MM-DD"),"-","/")&" "&INDEX('Airtable Input'!$A:$Z, 38, MATCH("Time_NZST", 'Airtable Input'!$1:$1, 0))),"") | B38: =IFERROR(IF(INDEX('Airtable Input'!$A:$Z, 38, MATCH("Caption_EN", 'Airtable Input'!$1:$1, 0))="","",INDEX('Airtable Input'!$A:$Z, 38, MATCH("Caption_EN", 'Airtable Input'!$1:$1, 0))&CHAR(10)&CHAR(10)&INDEX('Airtable Input'!$A:$Z, 38, MATCH("Hashtags_IG", 'Airtable Input'!$1:$1, 0))),"") | D38: =IFERROR(INDEX('Airtable Input'!$A:$Z, 38, MATCH("Image_URL", 'Airtable Input'!$1:$1, 0)),"") -> 0 | G38: =IFERROR(INDEX('Airtable Input'!$A:$Z, 38, MATCH("Headline_EN", 'Airtable Input'!$1:$1, 0)),"") -> 0 | H38: =IFERROR(IF(INDEX('Airtable Input'!$A:$Z, 38, MATCH("URL_Organic_UTM", 'Airtable Input'!$1:$1, 0))="","","🔗 Full details: "&INDEX('Airtable Input'!$A:$Z, 38, MATCH("URL_Organic_UTM", 'Airtable Input'!$1:$1, 0))),"") | I38: =IFERROR(IF(INDEX('Airtable Input'!$A:$Z, 38, MATCH("Format", 'Airtable Input'!$1:$1, 0))="Reel","Reel",IF(INDEX('Airtable Input'!$A:$Z, 38, MATCH("Format", 'Airtable Input'!$1:$1, 0))="Story","Story","")),"")
A39: =IFERROR(IF(INDEX('Airtable Input'!$A:$Z, 39, MATCH("Date", 'Airtable Input'!$1:$1, 0))="","",SUBSTITUTE(TEXT(INDEX('Airtable Input'!$A:$Z, 39, MATCH("Date", 'Airtable Input'!$1:$1, 0)),"YYYY-MM-DD"),"-","/")&" "&INDEX('Airtable Input'!$A:$Z, 39, MATCH("Time_NZST", 'Airtable Input'!$1:$1, 0))),"") | B39: =IFERROR(IF(INDEX('Airtable Input'!$A:$Z, 39, MATCH("Caption_EN", 'Airtable Input'!$1:$1, 0))="","",INDEX('Airtable Input'!$A:$Z, 39, MATCH("Caption_EN", 'Airtable Input'!$1:$1, 0))&CHAR(10)&CHAR(10)&INDEX('Airtable Input'!$A:$Z, 39, MATCH("Hashtags_IG", 'Airtable Input'!$1:$1, 0))),"") | D39: =IFERROR(INDEX('Airtable Input'!$A:$Z, 39, MATCH("Image_URL", 'Airtable Input'!$1:$1, 0)),"") -> 0 | G39: =IFERROR(INDEX('Airtable Input'!$A:$Z, 39, MATCH("Headline_EN", 'Airtable Input'!$1:$1, 0)),"") -> 0 | H39: =IFERROR(IF(INDEX('Airtable Input'!$A:$Z, 39, MATCH("URL_Organic_UTM", 'Airtable Input'!$1:$1, 0))="","","🔗 Full details: "&INDEX('Airtable Input'!$A:$Z, 39, MATCH("URL_Organic_UTM", 'Airtable Input'!$1:$1, 0))),"") | I39: =IFERROR(IF(INDEX('Airtable Input'!$A:$Z, 39, MATCH("Format", 'Airtable Input'!$1:$1, 0))="Reel","Reel",IF(INDEX('Airtable Input'!$A:$Z, 39, MATCH("Format", 'Airtable Input'!$1:$1, 0))="Story","Story","")),"")
A40: =IFERROR(IF(INDEX('Airtable Input'!$A:$Z, 40, MATCH("Date", 'Airtable Input'!$1:$1, 0))="","",SUBSTITUTE(TEXT(INDEX('Airtable Input'!$A:$Z, 40, MATCH("Date", 'Airtable Input'!$1:$1, 0)),"YYYY-MM-DD"),"-","/")&" "&INDEX('Airtable Input'!$A:$Z, 40, MATCH("Time_NZST", 'Airtable Input'!$1:$1, 0))),"") | B40: =IFERROR(IF(INDEX('Airtable Input'!$A:$Z, 40, MATCH("Caption_EN", 'Airtable Input'!$1:$1, 0))="","",INDEX('Airtable Input'!$A:$Z, 40, MATCH("Caption_EN", 'Airtable Input'!$1:$1, 0))&CHAR(10)&CHAR(10)&INDEX('Airtable Input'!$A:$Z, 40, MATCH("Hashtags_IG", 'Airtable Input'!$1:$1, 0))),"") | D40: =IFERROR(INDEX('Airtable Input'!$A:$Z, 40, MATCH("Image_URL", 'Airtable Input'!$1:$1, 0)),"") -> 0 | G40: =IFERROR(INDEX('Airtable Input'!$A:$Z, 40, MATCH("Headline_EN", 'Airtable Input'!$1:$1, 0)),"") -> 0 | H40: =IFERROR(IF(INDEX('Airtable Input'!$A:$Z, 40, MATCH("URL_Organic_UTM", 'Airtable Input'!$1:$1, 0))="","","🔗 Full details: "&INDEX('Airtable Input'!$A:$Z, 40, MATCH("URL_Organic_UTM", 'Airtable Input'!$1:$1, 0))),"") | I40: =IFERROR(IF(INDEX('Airtable Input'!$A:$Z, 40, MATCH("Format", 'Airtable Input'!$1:$1, 0))="Reel","Reel",IF(INDEX('Airtable Input'!$A:$Z, 40, MATCH("Format", 'Airtable Input'!$1:$1, 0))="Story","Story","")),"")
...
